awk: cmd. line:1: (FILENAME=/public/home/xiayini/project/nanopore_ATRX/3_1_methylation_analysis/results/filter2Reads/s31222_a509_2/chr1.merge.pileup FNR=193544031) fatal: more_nodes: nextfree: can't allocate 6400 bytes of memory (Cannot allocate memory)
awk: cmd. line:1: (FILENAME=/public/home/xiayini/project/nanopore_ATRX/3_1_methylation_analysis/results/filter2Reads/s31222_a509_2/chr2.merge.pileup FNR=146792092) fatal: more_nodes: nextfree: can't allocate 6400 bytes of memory (Cannot allocate memory)
multiprocessing.pool.RemoteTraceback: 
"""
Traceback (most recent call last):
  File "/public/home/xiayini/anaconda3/envs/sCell/lib/python3.9/multiprocessing/pool.py", line 125, in worker
    result = (True, func(*args, **kwds))
  File "/public/home/xiayini/anaconda3/envs/sCell/lib/python3.9/multiprocessing/pool.py", line 48, in mapstar
    return list(map(*args))
  File "/public/home/xiayini/project/nanopore_ATRX/3_1_methylation_analysis/scripts/join_comp/1_mu_sam_com.py", line 37, in process_chromosome
    folder_path, merge_file = sortedFile(chr, sample_name_list, old_folder_path)
  File "/public/home/xiayini/project/nanopore_ATRX/3_1_methylation_analysis/scripts/join_comp/1_mu_sam_com.py", line 11, in sortedFile
    os.makedirs(merge_folder_file)
  File "/public/home/xiayini/anaconda3/envs/sCell/lib/python3.9/os.py", line 225, in makedirs
    mkdir(name, mode)
FileExistsError: [Errno 17] File exists: '/public/home/xiayini/project/nanopore_ATRX/3_1_methylation_analysis/results/filter2Reads/s31222_a509_2'
"""

The above exception was the direct cause of the following exception:

Traceback (most recent call last):
  File "/public/home/xiayini/project/nanopore_ATRX/3_1_methylation_analysis/scripts/join_comp/1_mu_sam_com.py", line 61, in <module>
    pool.map(process_chromosome, chromosome_range)
  File "/public/home/xiayini/anaconda3/envs/sCell/lib/python3.9/multiprocessing/pool.py", line 364, in map
    return self._map_async(func, iterable, mapstar, chunksize).get()
  File "/public/home/xiayini/anaconda3/envs/sCell/lib/python3.9/multiprocessing/pool.py", line 771, in get
    raise self._value
FileExistsError: [Errno 17] File exists: '/public/home/xiayini/project/nanopore_ATRX/3_1_methylation_analysis/results/filter2Reads/s31222_a509_2'
